Workbook

Sheet OCT-19
B2: N° doc | C2: Fecha | D2: Monto Bruto | E2: Forma Pago | F2: 43753 | G2: 43754 | H2: 43755 | I2: 43756 | J2: 43757 | K2: 43758 | L2: 43759 | M2: 43760 | N2: 43761 | O2: 43762 | P2: 43763 | Q2: 43764 | R2: 43765 | S2: 43766 | T2: 43767 | U2: 43768 | V2: 43769
A3: SALDO INICIAL | F3: 0 | G3: =+F17 -> 250000 | H3: =+G17 -> 4335009.4 | I3: =+H17 -> 2818480.3 | J3: =+I17 -> 2818480.3 | K3: =+J17 -> 2818480.3 | L3: =+K17 -> 2818480.3 | M3: =+L17 -> 2818480.3 | N3: =+M17 -> 2818480.3 | ... V3: =+U17 -> 2818480.3
A4: INGRESOS
A5: Aporte LV | D5: 3000000 | F5: 250000 | G5: 2750000
A6: Aporte ML | D6: 3000000 | G6: 3000000
A8: TOTAL INGRESOS | F8: =SUM(F5:F7) -> 250000 | G8: =SUM(G5:G7) -> 5750000 | H8: =SUM(H5:H7) -> 0 | I8: =SUM(I5:I7) -> 0 | J8: =SUM(J5:J7) -> 0 | K8: =SUM(K5:K7) -> 0 | L8: =SUM(L5:L7) -> 0 | M8: =SUM(M5:M7) -> 0 | ... V8: =SUM(V5:V7) -> 0
A10: EGRESOS
A11: GECORP compra 2 equipos | B11: F22584 | C11: 43754 | D11: 1600990 | E11: TC EMS | G11: 1600990
A12: Boleta N°115 EMS Remun. Julio | B12: B115 | D12: 1500000 | E12: transferencia | H12: 1500000
A13: Anticipo Oficina Virtual Pro | B13: F3087 | D13: 64000 | E13: transferencia | G13: =48740*1.19+6000 -> 64000.6
A14: Certificado Electronico Simple | B14: F267835 | C14: 43755 | D14: 16529 | E14: TC EMS | H14: =13890*1.19 -> 16529.1
A16: TOTAL EGRESOS | F16: =SUM(F11:F15) -> 0 | G16: =SUM(G11:G15) -> 1664990.6 | H16: =SUM(H11:H15) -> 1516529.1 | I16: =SUM(I11:I15) -> 0 | J16: =SUM(J11:J15) -> 0 | K16: =SUM(K11:K15) -> 0 | L16: =SUM(L11:L15) -> 0 | M16: =SUM(M11:M15) -> 0 | ... V16: =SUM(V11:V15) -> 0
A17: SALDO FINAL | F17: =+F8+F3-F16 -> 250000 | G17: =+G3+G8-G16 -> 4335009.4 | H17: =+H3+H8-H16 -> 2818480.3 | I17: =+I3+I8-I16 -> 2818480.3 | J17: =+J3+J8-J16 -> 2818480.3 | K17: =+K3+K8-K16 -> 2818480.3 | L17: =+L3+L8-L16 -> 2818480.3 | M17: =+M3+M8-M16 -> 2818480.3 | N17: =+N3+N8-N16 -> 2818480.3 | ... V17: =+V3+V8-V16 -> 2818480.3

Sheet NOV-19
B2: N° doc | C2: Fecha | D2: Monto Bruto | E2: Forma Pago | F2: 43770 | G2: 43771 | H2: 43772 | I2: 43773 | J2: 43774 | K2: 43775 | L2: 43776 | M2: 43777 | N2: 43778 | O2: 43779 | P2: 43780 | Q2: 43781 | R2: 43782 | S2: 43783 | T2: 43784 | U2: 43785 | V2: 43786 | W2: 43787 | X2: 43788 | Y2: 43789 | Z2: 43790 | AA2: 43791 | AB2: 43792 | AC2: 43793 | AD2: 43794 | AE2: 43795 | AF2: 43796 | AG2: 43797 | AH2: 43798 | AI2: 43799
A3: SALDO INICIAL | F3: =+'OCT-19'!V17 -> 2818480.3 | G3: =+F27 -> 2818480.3 | H3: =+G27 -> 2818480.3 | I3: =+H27 -> 2818480.3 | J3: =+I27 -> 2818480.3 | K3: =+J27 -> 2318480.3 | L3: =+K27 -> 2318480.3 | M3: =+L27 -> 2318480.3 | N3: =+M27 -> 2296480.3 | ... AI3: =+AH27 -> 1470292.3
A4: INGRESOS
A6: Factura N° 2 Sofía Jottar | B6: F2 | C6: 43790 | D6: 160200
A7: Factura N° 3 Sofía Jottar | B7: F3 | C7: 43799 | D7: 267000
A8: Aporte LV | F8: 0 | G8: 0
A9: Aporte ML | G9: 0
A11: TOTAL INGRESOS | F11: =SUM(F8:F10) -> 0 | G11: =SUM(G8:G10) -> 0 | H11: =SUM(H8:H10) -> 0 | I11: =SUM(I8:I10) -> 0 | J11: =SUM(J8:J10) -> 0 | K11: =SUM(K8:K10) -> 0 | L11: =SUM(L8:L10) -> 0 | M11: =SUM(M8:M10) -> 0 | ... AI11: =SUM(AI8:AI10) -> 0
A13: EGRESOS
A15: Boleta N° 116 EMS Remun. Oct | B15: B116 | D15: 500000 | E15: transferencia | J15: 500000
A16: Harry Plotter sticker equipos | B16: F32253 | C16: 43777 | D16: 22000 | E16: TC | M16: 22000
A17: SIDTECH OC 100001 2 muebles | B17: F7 | C17: 43780 | D17: =559300 -> 559300 | E17: transferencias | X17: 200000 | Z17: 79650 | AF17: =559300/2 -> 279650
A18: SIDTECH OC 100002 | B18: F8 | C18: 43789 | D18: 125000 | E18: transferencias
A19: LIDER 3 camisas | B19: F 69885019 | C19: 43790 | D19: 12582 | E19: TC | Z19: 12582
A20: Bordado 3 camisas | B20: F 374 | C20: 43789 | D20: 11305 | E20: Transferencia | Z20: 11305
A21: Cilindro 9Kg CO2 | B21: F2485 | C21: 43791 | D21: 138000 | E21: TC | AA21: 138000
A22: Clean Ice Carga 2Kg CO2 | B22: F22146 | C22: 43796 | D22: 4760 | E22: transferencia | AF22: 4760
A23: SIDTECH OC 100003 | B23: F9 | C23: 43798 | D23: =179210*1.395 -> 249997.95 | E23: transferencia | AH23: 0
A24: Anticipo Oficina Virtual Pro | B24: F3087 | C24: 43799 | D24: 64000 | E24: transferencia
A25: RENDICION GASTOS | D25: =100241+56578 -> 156819 | AF25: =+[1]Nov!$B$13 -> 100241 | AI25: =+[1]Nov!$B$27 -> 56578
A26: TOTAL EGRESOS | F26: =SUM(F14:F25) -> 0 | G26: =SUM(G14:G25) -> 0 | H26: =SUM(H14:H25) -> 0 | I26: =SUM(I14:I25) -> 0 | J26: =SUM(J14:J25) -> 500000 | K26: =SUM(K14:K25) -> 0 | L26: =SUM(L14:L25) -> 0 | M26: =SUM(M14:M25) -> 22000 | ... AI26: =SUM(AI14:AI25) -> 56578
A27: SALDO FINAL | F27: =+F11+F3-F26 -> 2818480.3 | G27: =+G3+G11-G26 -> 2818480.3 | H27: =+H3+H11-H26 -> 2818480.3 | I27: =+I3+I11-I26 -> 2818480.3 | J27: =+J3+J11-J26 -> 2318480.3 | K27: =+K3+K11-K26 -> 2318480.3 | L27: =+L3+L11-L26 -> 2318480.3 | M27: =+M3+M11-M26 -> 2296480.3 | N27: =+N3+N11-N26 -> 2296480.3 | ... AI27: =+AI3+AI11-AI26 -> 1413714.3
D28: =+D16+D17+D18+D19+D20+D21+D22 -> 872947
D29: =+D28/1.19 -> 733568.91 | R29: =2296481+3508 -> 2299989
D30: =+D28-D29 -> 139378.09 | R30: =+R29-R27 -> 3508.7
R31: =+M16+'OCT-19'!D14+'OCT-19'!D13 -> 102529

Sheet DIC-19
B2: N° doc | C2: Fecha | D2: Monto Bruto | E2: Forma Pago | F2: 43800 | G2: 43801 | H2: 43802 | I2: 43803 | J2: 43804 | K2: 43805 | L2: 43806 | M2: 43807 | N2: 43808 | O2: 43809 | P2: 43810 | Q2: 43811 | R2: 43812 | S2: 43813 | T2: 43814 | U2: 43815 | V2: 43816 | W2: 43817 | X2: 43818 | Y2: 43819 | Z2: 43820 | AA2: 43821 | AB2: 43822 | AC2: 43823 | AD2: 43824 | AE2: 43825 | AF2: 43826 | AG2: 43827 | AH2: 43828 | AI2: 43829 | AJ2: 43830
A3: SALDO INICIAL | F3: =+'NOV-19'!AI27 -> 1413714.3 | G3: =+F32 -> 1413714.3 | H3: =+G32 -> 1413714.3 | I3: =+H32 -> 1413714.3 | J3: =+I32 -> 1413714.3 | K3: =+J32 -> 913714.3 | L3: =+K32 -> 747047.3 | M3: =+L32 -> 739067.3 | N3: =+M32 -> 739067.3 | ... AJ3: =+AI32 -> 2356809.4
A4: INGRESOS
A5: Factura N° 2 Sofía Jottar | B5: F2 | C5: 43790 | D5: 160200 | E5: cheque | W5: 160200
A6: Factura N° 3 Sofía Jottar | B6: F3 | C6: 43799 | D6: 267000 | E6: cheque
A7: Factura N° 4 Sofía Jottar | B7: F4 | C7: 43805 | D7: 267000 | E7: cheque
A8: Factura N° 5 Sofía Jottar | B8: F5 | C8: 43817 | D8: 267000 | E8: cheque
A9: Factura N° 6 Sofía Jottar | B9: F6 | C9: 43820 | D9: 267000 | E9: cheque
A11: Aporte LV
A12: Aporte ML | AI12: 2500000
A14: TOTAL INGRESOS | F14: =SUM(F5:F13) -> 0 | G14: =SUM(G5:G13) -> 0 | H14: =SUM(H5:H13) -> 0 | I14: =SUM(I5:I13) -> 0 | J14: =SUM(J5:J13) -> 0 | K14: =SUM(K5:K13) -> 0 | L14: =SUM(L5:L13) -> 0 | M14: =SUM(M5:M13) -> 0 | ... AJ14: =SUM(AJ5:AJ13) -> 0
A16: EGRESOS
A17: SIDTECH OC 100002 | B17: F8 | C17: 43789 | D17: 125000 | E17: transferencia | U17: 125000
A18: SIDTECH OC 100003 | B18: F9 | C18: 43798 | D18: =179210*1.395 -> 249997.95 | E18: transferencia | U18: =+D18 -> 249997.95
A19: SIDTECH arr reactor Entregas 19 y 21 de Nov | B19: F10 | C19: 43801 | D19: =162426*1.19 -> 193286.94 | E19: transferencia | AI19: =162426*1.19 -> 193286.94
A20: Boleta N° 117 EMS Remun Nov | B20: B117 | C20: 43804 | D20: 500000 | E20: transferencia | J20: 500000
A21: F29 OCT | C21: 43805 | D21: 166667 | E21: TC | K21: 166667
A22: F29 NOV | C22: 43811 | D22: 59146 | E22: TC | Q22: 59146
A23: Clean Ice Carga 2x 9Kg CO2 | B23: F22462 | C23: 43811 | D23: 32130 | E23: transferencia | Q23: =+D23 -> 32130
A24: SIDTECH OC 100004 200 lt | B24: F20 | C24: 43812 | D24: 250000 | E24: transferencia | L24: =3990*2 -> 7980 | AI24: 250000
A25: SIDTECH OC 100006 2 muebles | B25: F21 | C25: 43812 | D25: 559300
A26: Clean Ice Carga 2Kg CO2 | B26: F22540 | C26: 43815 | D26: 4760 | E26: transferencia | U26: =+D26 -> 4760
A27: INDURA REGULADOR PRESION | B27: F12404 | C27: 43822 | D27: 128137 | E27: TC | AB27: 128137
A28: Boleta N° 119 EMS Remun Agosto | B28: B119 | C28: 44196 | D28: 1500000 | E28: transferencia | AJ28: 1500000
A31: TOTAL EGRESOS | F31: =SUM(F17:F30) -> 0 | G31: =SUM(G17:G30) -> 0 | H31: =SUM(H17:H30) -> 0 | I31: =SUM(I17:I30) -> 0 | J31: =SUM(J17:J30) -> 500000 | K31: =SUM(K17:K30) -> 166667 | L31: =SUM(L17:L30) -> 7980 | M31: =SUM(M17:M30) -> 0 | ... AJ31: =SUM(AJ17:AJ30) -> 1500000
A32: SALDO FINAL | F32: =+F14+F3-F31 -> 1413714.3 | G32: =+G3+G14-G31 -> 1413714.3 | H32: =+H3+H14-H31 -> 1413714.3 | I32: =+I3+I14-I31 -> 1413714.3 | J32: =+J3+J14-J31 -> 913714.3 | K32: =+K3+K14-K31 -> 747047.3 | L32: =+L3+L14-L31 -> 739067.3 | M32: =+M3+M14-M31 -> 739067.3 | N32: =+N3+N14-N31 -> 739067.3 | ... AJ32: =+AJ3+AJ14-AJ31 -> 856809.41
K34: 1074022
K35: =+K32-K34 -> -326974.7
K36: =+'NOV-19'!D16+'NOV-19'!D19+'NOV-19'!D20+'NOV-19'!D21+'NOV-19'!D22+'NOV-19'!D25 -> 345466
K37: =+K36+K35 -> 18491.3
A39: Gastos con Boleta

Sheet ENE-20
B2: N° doc | C2: Fecha | D2: Monto Bruto | E2: Forma Pago | F2: 43831 | G2: 43832 | H2: 43833 | I2: 43834 | J2: 43835 | K2: 43836 | L2: 43837 | M2: 43838 | N2: 43839 | O2: 43840 | P2: 43841 | Q2: 43842 | R2: 43843 | S2: 43844 | T2: 43845 | U2: 43846 | V2: 43847 | W2: 43848 | X2: 43849 | Y2: 43850 | Z2: 43851 | AA2: 43852 | AB2: 43853 | AC2: 43854 | AD2: 43855 | AE2: 43856 | AF2: 43857 | AG2: 43858 | AH2: 43859 | AI2: 43860 | AJ2: 43861
A3: SALDO INICIAL | F3: =+'DIC-19'!AJ32 -> 856809.41 | G3: =+F41 -> 856809.41 | H3: =+G41 -> 856809.41 | I3: =+H41 -> -88840.59 | J3: =+I41 -> -88840.59 | K3: =+J41 -> -88840.59 | L3: =+K41 -> 2389889.4 | M3: =+L41 -> 2092813.4 | N3: =+M41 -> 1792813.4 | ... AJ3: =+AI41 -> 823697.41
A4: INGRESOS
A5: Factura N° 3 Sofía Jottar | B5: F3 | C5: 43799 | D5: 267000 | R5: =+D5 -> 267000
A6: Factura N° 4 Sofía Jottar | B6: F4 | C6: 43805 | D6: 267000 | E6: cheque | R6: =+D6 -> 267000
A7: Factura N° 5 Sofía Jottar | B7: F5 | C7: 43817 | D7: 267000 | E7: cheque
A8: Factura N° 6 Sofía Jottar | B8: F6 | C8: 43820 | D8: 267000 | E8: cheque
A9: Factura N° 7 Sofía Jottar | B9: F7 | C9: 43836 | D9: 267000 | E9: cheque
A10: Factura N° 8 Sofía Jottar | B10: F8 | C10: 43848 | D10: 160200 | E10: cheque
A11: Aporte LV | F11: 0 | G11: 0 | K11: 2500000
A12: Aporte ML | G12: 0
A16: TOTAL INGRESOS | F16: =SUM(F5:F15) -> 0 | G16: =SUM(G5:G15) -> 0 | H16: =SUM(H5:H15) -> 0 | I16: =SUM(I5:I15) -> 0 | J16: =SUM(J5:J15) -> 0 | K16: =SUM(K5:K15) -> 2500000 | L16: =SUM(L5:L15) -> 0 | M16: =SUM(M5:M15) -> 0 | ... AJ16: =SUM(AJ5:AJ15) -> 0
A18: EGRESOS
A19: SIDTECH OC 100007 | B19: F22 | C19: 43819 | D19: 250000 | E19: transferencia | O19: =+D19 -> 250000
A20: SIDTECH arr 2 reactor Entregas 19 y 21 de Nov | B20: F24 | C20: 43832 | D20: 177220 | E20: transferencia | AA20: =+D20 -> 177220
A21: GECORP compra 1 equipo 100 lt/min pinchadores devueltos | B21: F23501 | C21: 43833 | D21: 930125 | E21: TC EMS | H21: 930125
A22: GECORP compra accesorio equipo | B22: F23502 | C22: 43833 | D22: 3145 | E22: TC EMS | H22: 3145
A23: EASY PINTURA BLANCA MUEBLE | B23: F21509946 | C23: 43833 | D23: 12380 | E23: TC EMS | H23: 12380
A24: EASY PINTURA BLANCA MUEBLE BROCHA | B24: F21519808 | C24: 43836 | D24: 17580 | E24: TC EMS | K24: =+D24 -> 17580
A25: HOMECENTER arriendo caladora | B25: F102451374 | C25: 43836 | D25: 3690 | E25: TC EMS | K25: =+D25 -> 3690
A26: SIDTECH OC 100008 | B26: F25 | C26: 43836 | D26: 250000 | E26: transferencia | AH26: =+D26 -> 250000
A27: LANCER 2 regul, cil CO2 2.3Kg, mang | B27: F1065034 | C27: 43837 | D27: 297076 | E27: TC EMS | L27: =+D27 -> 297076
A28: Boleta N° 1 Brand Book | B28: B1 | C28: 43838 | D28: 440735 | E28: transferencia | M28: 300000 | R28: 140735
A29: ESMAX flete Casa Liberona a Huidobro a SIDTECH a Casa Mardones | B29: B168270027 | C29: 43840 | D29: 15024 | E29: TC EMS | O29: =+D29 -> 15024
A30: Boleta N° 120 EMS Remun Dic | B30: B120 | C30: 43841 | D30: 500000 | E30: transferencia | P30: =+D30 -> 500000
A31: F29 DIC | B31: 6895175876 | C31: 43843 | D31: =+R31 -> 228954 | E31: TC EMS | R31: 228954
A32: GECORP compra 1 equipo 100 lt/min pinchadores devueltos | B32: NC1990 | C32: 43843 | D32: -97968 | R32: =+D32 -> -97968
A33: Clean Ice Carga 2Kg CO2 | B33: F23187 | C33: 43844 | D33: 3570 | E33: transferencia | S33: =+D33 -> 3570
A34: COPEC flete a SIDTECH a JOTTAR a HUIDOBRO | B34: B856145 | C34: 43845 | D34: 17000 | E34: TC EMS | T34: =+D34 -> 17000
A35: UBER flete Cilindro CO2 SIDTECH a JOTTAR | C35: 43848 | D35: =+W35 -> 15011 | E35: TC EMS | W35: 15011
A36: Clean Ice Carga 2Kg CO2 | B36: F23402 | C36: 43853 | D36: 3570 | E36: transferencia | AB36: =+D36 -> 3570
A37: Flete Vitacura-Sofia Jottar | B37: B249931041 | C37: 43861 | D37: 7000 | E37: TC EMS | AJ37: =+D37 -> 7000
A40: TOTAL EGRESOS | F40: =SUM(F19:F39) -> 0 | G40: =SUM(G19:G39) -> 0 | H40: =SUM(H19:H39) -> 945650 | I40: =SUM(I19:I39) -> 0 | J40: =SUM(J19:J39) -> 0 | K40: =SUM(K19:K39) -> 21270 | L40: =SUM(L19:L39) -> 297076 | M40: =SUM(M19:M39) -> 300000 | ... AJ40: =SUM(AJ19:AJ39) -> 7000
A41: SALDO FINAL | F41: =+F16+F3-F40 -> 856809.41 | G41: =+G3+G16-G40 -> 856809.41 | H41: =+H3+H16-H40 -> -88840.59 | I41: =+I3+I16-I40 -> -88840.59 | J41: =+J3+J16-J40 -> -88840.59 | K41: =+K3+K16-K40 -> 2389889.4 | L41: =+L3+L16-L40 -> 2092813.4 | M41: =+M3+M16-M40 -> 1792813.4 | N41: =+N3+N16-N40 -> 1792813.4 | ... AJ41: =+AJ3+AJ16-AJ40 -> 816697.41

Sheet FEB-20
B2: N° doc | C2: Fecha | D2: Monto Bruto | E2: Forma Pago | F2: 43862 | G2: 43863 | H2: 43864 | I2: 43865 | J2: 43866 | K2: 43867 | L2: 43868 | M2: 43869 | N2: 43870 | O2: 43871 | P2: 43872 | Q2: 43873 | R2: 43874 | S2: 43875 | T2: 43876 | U2: 43877 | V2: 43878 | W2: 43879 | X2: 43880 | Y2: 43881 | Z2: 43882 | AA2: 43883 | AB2: 43884 | AC2: 43885 | AD2: 43886 | AE2: 43887 | AF2: 43888 | AG2: 43889 | AH2: 43890
A3: SALDO INICIAL | F3: =+'ENE-20'!AJ41 -> 816697.41 | G3: =+F42 -> 816697.41 | H3: =+G42 -> 816697.41 | I3: =+H42 -> 786632.41 | J3: =+I42 -> 786632.41 | K3: =+J42 -> 786632.41 | L3: =+K42 -> 774632.41 | M3: =+L42 -> 774632.41 | N3: =+M42 -> 774632.41 | ... AH3: =+AG42 -> -85085.59
A4: INGRESOS
A5: Factura N° 5 Sofía Jottar | B5: F5 | C5: 43817 | D5: 267000 | E5: cheque
A6: Factura N° 6 Sofía Jottar | B6: F6 | C6: 43820 | D6: 267000 | E6: cheque
A7: Factura N° 7 Sofía Jottar | B7: F7 | C7: 43836 | D7: 267000 | E7: cheque
A8: Factura N° 8 Sofía Jottar | B8: F8 | C8: 43848 | D8: 160200 | E8: cheque
A9: Factura N° 9 Sofía Jottar | B9: F9 | C9: 43865 | D9: 160200 | E9: cheque
A10: Factura N° 10 Sofía Jottar | B10: F10 | C10: 43866 | D10: 33728 | E10: cheque
A11: Factura N° 11 Sofía Jottar | B11: F11 | C11: 43876 | D11: 160200 | E11: cheque
A12: Factura N° 12 Sofía Jottar | B12: F12 | C12: 43882 | D12: 160200 | E12: cheque
A14: Aporte LV | F14: 0 | G14: 0
A15: Aporte ML | G15: 0
A18: TOTAL INGRESOS | F18: =SUM(F5:F17) -> 0 | G18: =SUM(G5:G17) -> 0 | H18: =SUM(H5:H17) -> 0 | I18: =SUM(I5:I17) -> 0 | J18: =SUM(J5:J17) -> 0 | K18: =SUM(K5:K17) -> 0 | L18: =SUM(L5:L17) -> 0 | M18: =SUM(M5:M17) -> 0 | ... AH18: =SUM(AH5:AH17) -> 0
A20: EGRESOS
A21: Clean Ice Carga 9Kg CO2 | B21: F23682 | C21: 43864 | D21: 16065 | E21: transferencia | H21: =+D21 -> 16065
A22: Flete Vitacura-CleanIce-Mercatelli-C.Huid-Gecorp-Vitacura | B22: B11294 | C22: 43864 | D22: 14000 | E22: TC EMS | H22: =+D22 -> 14000
A23: Boleta N° 121 EMS Remun Enero 2020 | B23: B121 | C23: 43867 | D23: 500000 | E23: transferencia | R23: =+D23 -> 500000
A24: Boleta N°122 Remun Variable Gerente | B24: B122 | C24: 43867 | D24: 118014 | R24: =('DIC-19'!W5+'ENE-20'!R5+'ENE-20'!R6)*0.17 -> 118014
A25: F29 Enero | C25: 43871 | D25: =+R25 -> 116900 | O25: =+'DIC-19'!J18*(1/0.9-1) -> 0 | R25: 116900
A26: Flete Vitacura-Gecorp-C.Huid-Mercatelli-Vitacura | B26: B255234562 | C26: 43867 | D26: 12000 | E26: TC EMS | K26: =+D26 -> 12000
A27: Flete Vitacura-S.Jottar-Vitacura | B27: B255856778 | C27: 43875 | D27: 7070 | E27: TC EMS | S27: 7070
A28: Flete Vitacura-S.Jottar-Vitacura | B28: B255857604 | C28: 43876 | D28: 7500 | E28: TC EMS | T28: 7500
A29: Flete Vitacura-El Establo-Cleanice-El Establo-S.Jottar-Vitacura | B29: B256141175 | C29: 43879 | D29: 13000 | E29: TC EMS | W29: 13000
A30: 10 botellas Sauvignon Blanc para test LANCER | B30: F31263917 | C30: 43879 | D30: 15959 | E30: TC EMS | W30: 15959
A31: Clean Ice Carga 9Kg+9Kg+2Kg CO2 | B31: F23989 | C31: 43879 | D31: 35700 | E31: transferencia | W31: 35700
A32: Flete Vitacura-CasaGH-S.Jottar-Vitacura | B32: B256243695 | C32: 43881 | D32: 8017 | E32: TC EMS | Y32: 8017
A33: Flete Vitacura-SIDTECH-CasaGH-S.Jottar-Vitacura | B33: B256329633 | C33: 43882 | D33: 14639 | E33: TC EMS | Z33: 14639
A34: UBER flete 60lt SIDTECH a JOTTAR | C34: 43882 | D34: 18185 | E34: TC EMS
A35: CALENDULA 1 lt alcohol de cereal | B35: F3136 | C35: 43885 | D35: 3325 | E35: TC EMS | AC35: 3325
A36: UBER flete 60lt SIDTECH a JOTTAR | C36: 43889 | D36: 19594 | E36: TC EMS | AG36: 19594
A41: TOTAL EGRESOS | F41: =SUM(F21:F37) -> 0 | G41: =SUM(G21:G37) -> 0 | H41: =SUM(H21:H37) -> 30065 | I41: =SUM(I21:I37) -> 0 | J41: =SUM(J21:J37) -> 0 | K41: =SUM(K21:K37) -> 12000 | L41: =SUM(L21:L37) -> 0 | M41: =SUM(M21:M37) -> 0 | ... AH41: =SUM(AH21:AH37) -> 0
A42: SALDO FINAL | F42: =+F18+F3-F41 -> 816697.41 | G42: =+G3+G18-G41 -> 816697.41 | H42: =+H3+H18-H41 -> 786632.41 | I42: =+I3+I18-I41 -> 786632.41 | J42: =+J3+J18-J41 -> 786632.41 | K42: =+K3+K18-K41 -> 774632.41 | L42: =+L3+L18-L41 -> 774632.41 | M42: =+M3+M18-M41 -> 774632.41 | N42: =+N3+N18-N41 -> 774632.41 | ... AH42: =+AH3+AH18-AH41 -> -85085.59

Sheet MAR-20
B2: N° doc | C2: Fecha | D2: Monto Bruto | E2: Forma Pago | F2: 43891 | G2: 43892 | H2: 43893 | I2: 43894 | J2: 43895 | K2: 43896 | L2: 43897 | M2: 43898 | N2: 43899 | O2: 43900 | P2: 43901 | Q2: 43902 | R2: 43903 | S2: 43904 | T2: 43905 | U2: 43906 | V2: 43907 | W2: 43908 | X2: 43909 | Y2: 43910 | Z2: 43911 | AA2: 43912 | AB2: 43913 | AC2: 43914 | AD2: 43915 | AE2: 43916 | AF2: 43917 | AG2: 43918 | AH2: 43919 | AI2: 43920 | AJ2: 43921
A3: SALDO INICIAL | F3: =+'FEB-20'!AH42 -> -85085.59 | G3: =+F58 -> -85085.59 | H3: =+G58 -> -85085.59 | I3: =+H58 -> -85085.59 | J3: =+I58 -> -85085.59 | K3: =+J58 -> -85085.59 | L3: =+K58 -> -85085.59 | M3: =+L58 -> -85085.59 | N3: =+M58 -> -85085.59 | ... AJ3: =+AI58 -> 1026449.7
A4: INGRESOS
A5: Factura N° 5 Sofía Jottar | B5: F5 | C5: 43817 | D5: 267000 | E5: cheque | AJ5: 0
A6: Factura N° 9 Sofía Jottar | B6: F9 | C6: 43865 | D6: 160200 | E6: cheque
A7: Factura N° 10 Sofía Jottar | B7: F10 | C7: 43866 | D7: 33728 | E7: cheque
A8: Factura N° 11 Sofía Jottar | B8: F11 | C8: 43876 | D8: 160200 | E8: cheque
A9: Factura N° 12 Sofía Jottar | B9: F12 | C9: 43882 | D9: 160200 | E9: cheque
D10: =SUM(D6:D9)*1.19 -> 612050.32
A11: Aporte LV | F11: 0 | G11: 0
A12: Aporte ML | D12: 2500000 | G12: 0 | W12: 2500000
A13: Remanente IVA
A16: TOTAL INGRESOS | F16: =SUM(F5:F15) -> 0 | G16: =SUM(G5:G15) -> 0 | H16: =SUM(H5:H15) -> 0 | I16: =SUM(I5:I15) -> 0 | J16: =SUM(J5:J15) -> 0 | K16: =SUM(K5:K15) -> 0 | L16: =SUM(L5:L15) -> 0 | M16: =SUM(M5:M15) -> 0 | ... AJ16: =SUM(AJ5:AJ15) -> 0
A18: EGRESOS
A19: Flete Vitacura-SJottar-Vitacura | B19: B258439138 | C19: 43906 | D19: 4278 | E19: TC EMS | U19: 4278
A20: SIDTECH arr 3 reactor Entregas 19 y 21 de Nov y 15 de Enero | B20: F26 | C20: 43864 | D20: 285243 | E20: =+D20/3 -> 95081 | AJ20: 0
A21: SIDTECH mueble+vino | B21: F27 | C21: 43884 | D21: 253499 | W21: 253499
A22: SIDTECH arr 3 reactor Entregas 19 y 21 de Nov y 15 de Enero+vino | B22: F28 | C22: 43890 | D22: 220655 | E22: =+(81600+3*21008)*1.19 -> 172102.56
A23: ANALAB preparación mezcla Aperol | B23: F194283 | C23: 43892 | D23: =45500*1.19 -> 54145 | G23: 0
A24: Boleta N° 123 EMS Remun Febrero 2020 | B24: B123 | C24: 43896 | D24: 500000 | E24: transferencia | W24: =+D24 -> 500000
A25: Flete Vitacura-SIDTECH-Vitacura | B25: B2237829 | C25: 43900 | D25: 8500 | E25: TC EMS | O25: 8500
A26: F29 Febrero | C26: 43902 | D26: 75855.737 | X26: =+(('FEB-20'!D23+'FEB-20'!D24)/0.8925)*0.1075+0.0025*SUM('ABR-20'!D9:D13)/1.19 -> 75855.737
A27: Clean Ice Carga 9Kg+2Kg CO2 | B27: F24588 | C27: 43902 | D27: 19635 | E27: transferencia | Q27: 19635
A28: FERSOL tambor 60 lt una boca | B28: F3861 | C28: 43902 | D28: 11662 | E28: transferencia | Q28: 11662
A29: CALENDULA 4 lt alcohol de cereal | B29: F3265 | C29: 43902 | D29: 14000 | E29: TC EMS | Q29: 14000
A30: Flete Vitacura-Cleanice-Wenco-Fersol-Sjottar-Vitacura | B30: B258222749 | C30: 43902 | D30: 15903 | E30: TC EMS | Q30: 15903
A31: UNIMARC 8X6 LT agua+5 kg azucar | B31: F31511712 | C31: 43902 | D31: 14490 | E31: TC EMS | Q31: 14490
A32: SABORES Ltda. Ingredientes Aperol | B32: F84289 | C32: 43902 | D32: 116875 | E32: transferencia | Q32: 116875
A33: FERNAPET Balanza 500 +/- 1 gramo | B33: F58956 | C33: 43902 | D33: 4990 | E33: TC EMS | Q33: 4990
A34: Flete Vitacura-SIDTECH-S.Jottar-Vitacura | B34: B258279430 | C34: 43903 | D34: 15000 | E34: TC EMS | R34: 15000
A35: Flete Vitacura-SJottar-Vitacura | B35: B258333151 | C35: 43904 | D35: 7037 | E35: TC EMS | S35: 7037
A36: SIDTECH vino | B36: F29 | C36: 43905 | D36: 125998
A37: TOTTUS alargador electrico | B37: B484741684 | C37: 43906 | D37: 3990 | E37: TC EMS | U37: 3990
A38: SIDTECH vino+mezcla+llenado Spritz | B38: F30 | C38: 43906 | D38: 24395
A39: SIDTECH OC 100010 1000 lt vino abono 20% | B39: F32 | C39: 43909 | D39: 250007 | E39: transferencia | W39: 250000
A40: Flete Vitacura-Chicureo-Vitacura 18 y 20 Marzo | B40: B258613719 | C40: 43910 | D40: 14750 | E40: TC EMS | Y40: 14750
A41: Oficina Virtual | B41: F36 | C41: 43916 | D41: =58000 -> 58000 | E41: transferencia | W41: 58000
A42: SIDTECH arr 3 reactor Entregas 19 y 21 de Nov y 15 de Enero | B42: F33 | C42: 43920 | D42: 149048 | E42: =83500*1.19*14/30 -> 46370.333
C44: AF | D44: =+D21+D28+D33+D37 -> 274141
A48: Insumos 500 lt Laura Seyler Spritz | B48: xxxx | C48: xxx | D48: 370000
...

Sheet ABR-20
B2: N° doc | C2: Fecha | D2: Monto Bruto | E2: Forma Pago | F2: 43922 | G2: 43923 | H2: 43924 | I2: 43925 | J2: 43926 | K2: 43927 | L2: 43928 | M2: 43929 | N2: 43930 | O2: 43931 | P2: 43932 | Q2: 43933 | R2: 43934 | S2: 43935 | T2: 43936 | U2: 43937 | V2: 43938 | W2: 43939 | X2: 43940 | Y2: 43941 | Z2: 43942 | AA2: 43943 | AB2: 43944 | AC2: 43945 | AD2: 43946 | AE2: 43947 | AF2: 43948 | AG2: 43949 | AH2: 43950 | AI2: 43951
A3: SALDO INICIAL | F3: =+'MAR-20'!AJ58 -> 1026449.7 | G3: =+F34 -> 1026449.7 | H3: =+G34 -> 1026449.7 | I3: =+H34 -> 1026449.7 | J3: =+I34 -> 1026449.7 | K3: =+J34 -> 1026449.7 | L3: =+K34 -> 1026449.7 | M3: =+L34 -> 1026449.7 | N3: =+M34 -> 1293449.7 | ... AI3: =+AH34 -> 97707.584
A4: INGRESOS
A5: Factura N° 5 Sofía Jottar | B5: F5 | C5: 43817 | D5: 267000 | E5: transferencia | M5: 267000
A6: Factura N° 6 Sofía Jottar | B6: F6 | C6: 43820 | D6: 267000 | E6: cheque
A7: Factura N° 7 Sofía Jottar | B7: F7 | C7: 43836 | D7: 267000 | E7: cheque
A8: Factura N° 8 Sofía Jottar | B8: F8 | C8: 43848 | D8: 160200 | E8: cheque
A9: Factura N° 9 Sofía Jottar | B9: F9 | C9: 43865 | D9: 160200 | E9: cheque
A10: Factura N° 10 Sofía Jottar | B10: F10 | C10: 43866 | D10: 33728 | E10: cheque
A11: Factura N° 11 Sofía Jottar | B11: F11 | C11: 43876 | D11: 160200 | E11: cheque
A12: Factura N° 12 Sofía Jottar | B12: F12 | C12: 43882 | D12: 160200 | E12: cheque
A13: Factura N° 13 Sofía Jottar | B13: F13 | C13: 43889 | D13: 160200 | E13: cheque
A14: Factura N° 14 Sofía Jottar | B14: F14 | C14: 43892 | D14: =28475.41*1.19 -> 33885.738 | E14: cheque
A15: Factura N° 15 Sofía Jottar | B15: F15 | C15: 43904 | D15: 160200 | E15: cheque
A16: Factura N° XX Sofía Jottar SPRITZ | B16: FXX | D16: =4500*60 -> 270000
A18: Aporte LV | F18: 0 | G18: 0
A19: Aporte ML | G19: 0
A20: Remanente IVA | D20: 2001574
A23: TOTAL INGRESOS | F23: =SUM(F6:F22) -> 0 | G23: =SUM(G6:G22) -> 0 | H23: =SUM(H6:H22) -> 0 | I23: =SUM(I6:I22) -> 0 | J23: =SUM(J6:J22) -> 0 | K23: =SUM(K6:K22) -> 0 | L23: =SUM(L6:L22) -> 0 | M23: =SUM(M5:M22) -> 267000 | N23: =SUM(N6:N22) -> 0 | O23: =SUM(O6:O22) -> 0 | P23: =SUM(P6:P22) -> 0 | Q23: =SUM(Q6:Q22) -> 0 | R23: =SUM(R6:R22) -> 0 | S23: =SUM(S6:S22) -> 0 | T23: =SUM(T6:T22) -> 0 | U23: =SUM(U6:U22) -> 0 | ... AI23: =SUM(AI6:AI22) -> 0
A25: EGRESOS
A26: SIDTECH vino+mezcla+llenado Spritz | B26: F30 | C26: 43906 | D26: 24395 | E26: transferencia | S26: 24395
A27: SIDTECH vino | B27: F29 | C27: 43905 | D27: 124998 | AF27: 124998
A28: Boleta N° 124 EMS Remun Marzo 2020 | B28: B124 | C28: 43926 | D28: 500000 | O28: 500000
A29: F29 Marzo | O29: =+'MAR-20'!W24*0.1075/0.8925+('ABR-20'!D14+'ABR-20'!D15)*0.0025*0 -> 60224.09
A30: Boleta N° 2 saldo Brand Book | B30: B2 | D30: 440735 | N30: 440735
A31: Boleta N°125 Remun Variable Gerente | B31: B125 | D31: 45390 | O31: =+M5*0.17 -> 45390
A33: TOTAL EGRESOS | F33: =SUM(F26:F32) -> 0 | G33: =SUM(G26:G32) -> 0 | H33: =SUM(H26:H32) -> 0 | I33: =SUM(I26:I32) -> 0 | J33: =SUM(J26:J32) -> 0 | K33: =SUM(K26:K32) -> 0 | L33: =SUM(L26:L32) -> 0 | M33: =SUM(M26:M32) -> 0 | ... AI33: =SUM(AI26:AI32) -> 0
A34: SALDO FINAL | F34: =+F23+F3-F33 -> 1026449.7 | G34: =+G3+G23-G33 -> 1026449.7 | H34: =+H3+H23-H33 -> 1026449.7 | I34: =+I3+I23-I33 -> 1026449.7 | J34: =+J3+J23-J33 -> 1026449.7 | K34: =+K3+K23-K33 -> 1026449.7 | L34: =+L3+L23-L33 -> 1026449.7 | M34: =+M3+M23-M33 -> 1293449.7 | N34: =+N3+N23-N33 -> 852714.67 | ... AI34: =+AI3+AI23-AI33 -> 97707.584

Sheet MAY-20
B2: N° doc | C2: Fecha | D2: Monto Bruto | E2: Forma Pago | F2: 43952 | G2: 43953 | H2: 43954 | I2: 43955 | J2: 43956 | K2: 43957 | L2: 43958 | M2: 43959 | N2: 43960 | O2: 43961 | P2: 43962 | Q2: 43963 | R2: 43964 | S2: 43965 | T2: 43966 | U2: 43967 | V2: 43968 | W2: 43969 | X2: 43970 | Y2: 43971 | Z2: 43972 | AA2: 43973 | AB2: 43974 | AC2: 43975 | AD2: 43976 | AE2: 43977 | AF2: 43978 | AG2: 43979 | AH2: 43980 | AI2: 43981 | AJ2: 43982
A3: SALDO INICIAL | F3: =+'ABR-20'!AI34 -> 97707.584 | G3: =+F33 -> 97707.584 | H3: =+G33 -> 97707.584 | I3: =+H33 -> 97707.584 | J3: =+I33 -> 97707.584 | K3: =+J33 -> -2292.4163 | L3: =+K33 -> -2292.4163 | M3: =+L33 -> -2292.4163 | N3: =+M33 -> -2292.4163 | ... AJ3: =+AI33 -> -2292.4163
A4: INGRESOS
A5: Factura N° 6 Sofía Jottar | B5: F6 | C5: 43820 | D5: 267000
A6: Factura N° 7 Sofía Jottar | B6: F7 | C6: 43836 | D6: 267000
A7: Factura N° 8 Sofía Jottar | B7: F8 | C7: 43848 | D7: 160200
A8: Factura N° 9 Sofía Jottar | B8: F9 | C8: 43865 | D8: 160200
A9: Factura N° 10 Sofía Jottar | B9: F10 | C9: 43866 | D9: 33728
A10: Factura N° 11 Sofía Jottar | B10: F11 | C10: 43876 | D10: 160200
A11: Factura N° 12 Sofía Jottar | B11: F12 | C11: 43882 | D11: 160200
A12: Factura N° 13 Sofía Jottar | B12: F13 | C12: 43889 | D12: 160200
A13: Factura N° 14 Sofía Jottar | B13: F14 | C13: 43892 | D13: =28475.41*1.19 -> 33885.738
A14: Factura N° 15 Sofía Jottar | B14: F15 | C14: 43904 | D14: 160200
A15: Factura N° XX Sofía Jottar SPRITZ | B15: FXX | D15: =4500*60 -> 270000 | E15: por facturar
A17: Aporte LV | F17: 0 | G17: 0
A18: Aporte ML | G18: 0
A19: Remanente IVA | D19: 2001574
A22: TOTAL INGRESOS | F22: =SUM(F5:F21) -> 0 | G22: =SUM(G5:G21) -> 0 | H22: =SUM(H5:H21) -> 0 | I22: =SUM(I5:I21) -> 0 | J22: =SUM(J5:J21) -> 0 | K22: =SUM(K5:K21) -> 0 | L22: =SUM(L5:L21) -> 0 | M22: =SUM(M5:M21) -> 0 | ... AJ22: =SUM(AJ5:AJ21) -> 0
A24: EGRESOS
A25: SIDTECH OC 100006 2 muebles | B25: F21 | C25: 43812 | D25: 559300
A26: Boleta N° xxx EMS Remun Abril 2020 | B26: Bxxx | D26: 500000
A27: Boleta N°xxx Remun Variable Gerente | B27: Bxxx | D27: =+(D5+D6+D7)*0.17 -> 118014
A28: SIDTECH OC 100010 1000 lt vino saldo 80% | B28: FXX | D28: =1250000-250000- 2150*1.19*100 -> 744150
A29: SIDTECH arr 3 reactor Entregas 19 y 21 de Nov y 15 de Enero | B29: F26 | C29: 43864 | D29: 285243
A30: Pyme Asesores Declaracion Renta | B30: F Ex 493 | D30: 100000 | J30: 100000
A32: TOTAL EGRESOS | F32: =SUM(F25:F31) -> 0 | G32: =SUM(G25:G31) -> 0 | H32: =SUM(H25:H31) -> 0 | I32: =SUM(I25:I31) -> 0 | J32: =SUM(J25:J31) -> 100000 | K32: =SUM(K25:K31) -> 0 | L32: =SUM(L25:L31) -> 0 | M32: =SUM(M25:M31) -> 0 | ... AJ32: =SUM(AJ25:AJ31) -> 0
A33: SALDO FINAL | F33: =+F22+F3-F32 -> 97707.584 | G33: =+G3+G22-G32 -> 97707.584 | H33: =+H3+H22-H32 -> 97707.584 | I33: =+I3+I22-I32 -> 97707.584 | J33: =+J3+J22-J32 -> -2292.4163 | K33: =+K3+K22-K32 -> -2292.4163 | L33: =+L3+L22-L32 -> -2292.4163 | M33: =+M3+M22-M32 -> -2292.4163 | N33: =+N3+N22-N32 -> -2292.4163 | ... AJ33: =+AJ3+AJ22-AJ32 -> -2292.4163

Sheet JUN-20
B2: N° doc | C2: Fecha | D2: Monto Bruto | E2: Forma Pago | F2: 43983 | G2: 43984 | H2: 43985 | I2: 43986 | J2: 43987 | K2: 43988 | L2: 43989 | M2: 43990 | N2: 43991 | O2: 43992 | P2: 43993 | Q2: 43994 | R2: 43995 | S2: 43996 | T2: 43997 | U2: 43998 | V2: 43999 | W2: 44000 | X2: 44001 | Y2: 44002 | Z2: 44003 | AA2: 44004 | AB2: 44005 | AC2: 44006 | AD2: 44007 | AE2: 44008 | AF2: 44009 | AG2: 44010 | AH2: 44011 | AI2: 44012
A3: SALDO INICIAL | F3: =+'MAY-20'!AJ33 -> -2292.4163 | G3: =+F35 -> -2292.4163 | H3: =+G35 -> -2292.4163 | I3: =+H35 -> -2292.4163 | J3: =+I35 -> -2292.4163 | K3: =+J35 -> -2292.4163 | L3: =+K35 -> -2292.4163 | M3: =+L35 -> -2292.4163 | N3: =+M35 -> -2292.4163 | ... AI3: =+AH35 -> -2292.4163
A4: INGRESOS
A5: Factura N° 6 Sofía Jottar | B5: F6 | C5: 43820 | D5: 267000
A6: Factura N° 7 Sofía Jottar | B6: F7 | C6: 43836 | D6: 267000
A7: Factura N° 8 Sofía Jottar | B7: F8 | C7: 43848 | D7: 160200
A8: Factura N° 9 Sofía Jottar | B8: F9 | C8: 43865 | D8: 160200
A9: Factura N° 10 Sofía Jottar | B9: F10 | C9: 43866 | D9: 33728
A10: Factura N° 11 Sofía Jottar | B10: F11 | C10: 43876 | D10: 160200
A11: Factura N° 12 Sofía Jottar | B11: F12 | C11: 43882 | D11: 160200
A12: Factura N° 13 Sofía Jottar | B12: F13 | C12: 43889 | D12: 160200
A13: Factura N° 14 Sofía Jottar | B13: F14 | C13: 43892 | D13: =28475.41*1.19 -> 33885.738
A14: Factura N° 15 Sofía Jottar | B14: F15 | C14: 43904 | D14: 160200
A15: Factura N° XX Sofía Jottar SPRITZ | B15: FXX | D15: =4500*60 -> 270000 | E15: por facturar
A16: GECORP N/C 1990 | B16: NC 1990 | C16: 43843 | D16: 97968 | AI16: =+D16 -> 97968
A17: SII DEVOLUCION PPM 2019
A19: Aporte LV | F19: 0 | G19: 0
A20: Aporte ML | G20: 0
A21: Remanente IVA | D21: 2001574
A24: TOTAL INGRESOS | F24: =SUM(F5:F23) -> 0 | G24: =SUM(G5:G23) -> 0 | H24: =SUM(H5:H23) -> 0 | I24: =SUM(I5:I23) -> 0 | J24: =SUM(J5:J23) -> 0 | K24: =SUM(K5:K23) -> 0 | L24: =SUM(L5:L23) -> 0 | M24: =SUM(M5:M23) -> 0 | ... AI24: =SUM(AI5:AI23) -> 97968
A26: EGRESOS
A27: SIDTECH OC 100006 2 muebles | B27: F21 | C27: 43812 | D27: 559300
A28: Boleta N° xxx EMS Remun Abril 2020 | B28: Bxxx | D28: 500000
A29: Boleta N° xxx EMS Remun Mayo 2020 | B29: Bxxx | D29: 500000
A30: Boleta N°xxx Remun Variable Gerente | B30: Bxxx | D30: =+(D5+D6+D7)*0.17 -> 118014
A31: SIDTECH OC 100010 1000 lt vino saldo 80% | B31: FXX | D31: =1250000-250000- 2150*1.19*100 -> 744150
A32: SIDTECH arr 3 reactor Entregas 19 y 21 de Nov y 15 de Enero | B32: F26 | C32: 43864 | D32: 285243
A34: TOTAL EGRESOS | F34: =SUM(F27:F33) -> 0 | G34: =SUM(G27:G33) -> 0 | H34: =SUM(H27:H33) -> 0 | I34: =SUM(I27:I33) -> 0 | J34: =SUM(J27:J33) -> 0 | K34: =SUM(K27:K33) -> 0 | L34: =SUM(L27:L33) -> 0 | M34: =SUM(M27:M33) -> 0 | ... AI34: =SUM(AI27:AI33) -> 0
A35: SALDO FINAL | F35: =+F24+F3-F34 -> -2292.4163 | G35: =+G3+G24-G34 -> -2292.4163 | H35: =+H3+H24-H34 -> -2292.4163 | I35: =+I3+I24-I34 -> -2292.4163 | J35: =+J3+J24-J34 -> -2292.4163 | K35: =+K3+K24-K34 -> -2292.4163 | L35: =+L3+L24-L34 -> -2292.4163 | M35: =+M3+M24-M34 -> -2292.4163 | N35: =+N3+N24-N34 -> -2292.4163 | ... AI35: =+AI3+AI24-AI34 -> 95675.584

Sheet JUL-20
B2: N° doc | C2: Fecha | D2: Monto Bruto | E2: Forma Pago | F2: 44013 | G2: 44014 | H2: 44015 | I2: 44016 | J2: 44017 | K2: 44018 | L2: 44019 | M2: 44020 | N2: 44021 | O2: 44022 | P2: 44023 | Q2: 44024 | R2: 44025 | S2: 44026 | T2: 44027 | U2: 44028 | V2: 44029 | W2: 44030 | X2: 44031 | Y2: 44032 | Z2: 44033 | AA2: 44034 | AB2: 44035 | AC2: 44036 | AD2: 44037 | AE2: 44038 | AF2: 44039 | AG2: 44040 | AH2: 44041 | AI2: 44042 | AJ2: 44043
A3: SALDO INICIAL | F3: =+'JUN-20'!AI35 -> 95675.584 | G3: =+F38 -> 95675.584 | H3: =+G38 -> 95675.584 | I3: =+H38 -> 95675.584 | J3: =+I38 -> 95675.584 | K3: =+J38 -> 95675.584 | L3: =+K38 -> 95675.584 | M3: =+L38 -> 95675.584 | N3: =+M38 -> 95675.584 | ... AJ3: =+AI38 -> 62605.584
A4: INGRESOS
A5: Factura N° 6 Sofía Jottar | B5: F6 | C5: 43820 | D5: 267000
A6: Factura N° 7 Sofía Jottar | B6: F7 | C6: 43836 | D6: 267000
A7: Factura N° 8 Sofía Jottar | B7: F8 | C7: 43848 | D7: 160200
A8: Factura N° 9 Sofía Jottar | B8: F9 | C8: 43865 | D8: 160200
A9: Factura N° 10 Sofía Jottar | B9: F10 | C9: 43866 | D9: 33728
A10: Factura N° 11 Sofía Jottar | B10: F11 | C10: 43876 | D10: 160200
A11: Factura N° 12 Sofía Jottar | B11: F12 | C11: 43882 | D11: 160200
A12: Factura N° 13 Sofía Jottar | B12: F13 | C12: 43889 | D12: 160200
A13: Factura N° 14 Sofía Jottar | B13: F14 | C13: 43892 | D13: =28475.41*1.19 -> 33885.738
A14: Factura N° 15 Sofía Jottar | B14: F15 | C14: 43904 | D14: 160200
A15: Factura N° XX Sofía Jottar SPRITZ | B15: FXX | D15: =4500*60 -> 270000 | E15: por facturar
A16: SII DEVOLUCION PPM 2019 | C16: 43980 | D16: 10465 | V16: 0
A18: Aporte LV | F18: 0 | G18: 0
A19: Aporte ML | G19: 0
A20: Remanente IVA | D20: 2001574
A23: TOTAL INGRESOS | F23: =SUM(F5:F22) -> 0 | G23: =SUM(G5:G22) -> 0 | H23: =SUM(H5:H22) -> 0 | I23: =SUM(I5:I22) -> 0 | J23: =SUM(J5:J22) -> 0 | K23: =SUM(K5:K22) -> 0 | L23: =SUM(L5:L22) -> 0 | M23: =SUM(M5:M22) -> 0 | ... AJ23: =SUM(AJ5:AJ22) -> 0
A25: EGRESOS
A26: SIDTECH OC 100006 2 muebles | B26: F21 | C26: 43812 | D26: 559300
A27: Boleta N° xxx EMS Remun Abril 2020 | B27: Bxxx | D27: 500000
A28: Boleta N° xxx EMS Remun Mayo 2020 | B28: Bxxx | D28: 500000
A29: Boleta N° xxx EMS Remun Junio 2020 | B29: Bxxx | D29: =500000/2 -> 250000
A30: Boleta N°xxx Remun Variable Gerente | B30: Bxxx | D30: =+(D5+D6+D7)*0.17 -> 118014
A31: SIDTECH OC 100010 1000 lt vino saldo 80% | B31: FXX | D31: =1250000-250000- 2150*1.19*100 -> 744150
A32: SIDTECH arr 3 reactor Entregas 19 y 21 de Nov y 15 de Enero | B32: F26 | C32: 43864 | D32: 285243
A33: Corretajes Torres | B33: F1130 | C33: 44004 | D33: =7500*1.19 -> 8925 | O33: =7500*1.19 -> 8925
A34: ANALAB preparación mezcla Aperol | B34: F194283 | C34: 43892 | D34: =45500*1.19 -> 54145 | O34: =54145-30000 -> 24145
A37: TOTAL EGRESOS | F37: =SUM(F26:F34) -> 0 | G37: =SUM(G26:G34) -> 0 | H37: =SUM(H26:H34) -> 0 | I37: =SUM(I26:I34) -> 0 | J37: =SUM(J26:J34) -> 0 | K37: =SUM(K26:K34) -> 0 | L37: =SUM(L26:L34) -> 0 | M37: =SUM(M26:M34) -> 0 | ... AJ37: =SUM(AJ26:AJ34) -> 0
A38: SALDO FINAL | F38: =+F23+F3-F37 -> 95675.584 | G38: =+G3+G23-G37 -> 95675.584 | H38: =+H3+H23-H37 -> 95675.584 | I38: =+I3+I23-I37 -> 95675.584 | J38: =+J3+J23-J37 -> 95675.584 | K38: =+K3+K23-K37 -> 95675.584 | L38: =+L3+L23-L37 -> 95675.584 | M38: =+M3+M23-M37 -> 95675.584 | N38: =+N3+N23-N37 -> 95675.584 | ... AJ38: =+AJ3+AJ23-AJ37 -> 62605.584

Sheet AGO-20
B2: N° doc | C2: Fecha | D2: Monto Bruto | E2: Forma Pago | F2: 44044 | G2: 44045 | H2: 44046 | I2: 44047 | J2: 44048 | K2: 44049 | L2: 44050 | M2: 44051 | N2: 44052 | O2: 44053 | P2: 44054 | Q2: 44055 | R2: 44056 | S2: 44057 | T2: 44058 | U2: 44059 | V2: 44060 | W2: 44061 | X2: 44062 | Y2: 44063 | Z2: 44064 | AA2: 44065 | AB2: 44066 | AC2: 44067 | AD2: 44068 | AE2: 44069 | AF2: 44070 | AG2: 44071 | AH2: 44072 | AI2: 44073 | AJ2: 44074
A3: SALDO INICIAL | F3: =+'JUL-20'!AJ38 -> 62605.584 | G3: =+F44 -> 62605.584 | H3: =+G44 -> 62605.584 | I3: =+H44 -> 62605.584 | J3: =+I44 -> 62605.584 | K3: =+J44 -> 62605.584 | L3: =+K44 -> -2145.4163 | M3: =+L44 -> -2145.4163 | N3: =+M44 -> -2145.4163 | ... AJ3: =+AI44 -> -18210.416
A4: INGRESOS
A5: Factura N° 6 Sofía Jottar | B5: F6 | C5: 43820 | D5: 267000
A6: Factura N° 7 Sofía Jottar | B6: F7 | C6: 43836 | D6: 267000
A7: Factura N° 8 Sofía Jottar | B7: F8 | C7: 43848 | D7: 160200
A8: Factura N° 9 Sofía Jottar | B8: F9 | C8: 43865 | D8: 160200
A9: Factura N° 10 Sofía Jottar | B9: F10 | C9: 43866 | D9: 33728
A10: Factura N° 11 Sofía Jottar | B10: F11 | C10: 43876 | D10: 160200
A11: Factura N° 12 Sofía Jottar | B11: F12 | C11: 43882 | D11: 160200
A12: Factura N° 13 Sofía Jottar | B12: F13 | C12: 43889 | D12: 160200
A13: Factura N° 14 Sofía Jottar | B13: F14 | C13: 43892 | D13: =28475.41*1.19 -> 33885.738
A14: Factura N° 15 Sofía Jottar | B14: F15 | C14: 43904 | D14: 160200
A15: Factura N° XX Sofía Jottar SPRITZ | B15: FXX | D15: =4500*60 -> 270000 | E15: por facturar
A16: SII DEVOLUCION PPM 2019 | C16: 43980 | D16: 10465
A18: Aporte LV | F18: 0 | G18: 0
A19: Aporte ML | G19: 0
A20: Remanente IVA | D20: 2001574
A23: TOTAL INGRESOS | F23: =SUM(F5:F22) -> 0 | G23: =SUM(G5:G22) -> 0 | H23: =SUM(H5:H22) -> 0 | I23: =SUM(I5:I22) -> 0 | J23: =SUM(J5:J22) -> 0 | K23: =SUM(K5:K22) -> 0 | L23: =SUM(L5:L22) -> 0 | M23: =SUM(M5:M22) -> 0 | ... AJ23: =SUM(AJ5:AJ22) -> 0
A25: EGRESOS
A26: SIDTECH OC 100006 2 muebles | B26: F21 | C26: 43812 | D26: 559300
A27: Boleta N° xxx EMS Remun Abril 2020 | B27: Bxxx | D27: 500000
A28: Boleta N° xxx EMS Remun Mayo 2020 | B28: Bxxx | D28: 500000
A29: Boleta N° xxx EMS Remun Junio 2020 | B29: Bxxx | D29: =500000/2 -> 250000
A30: Boleta N° xxx EMS Remun Julio 2020 | B30: Bxxx | D30: =500000/2 -> 250000
A31: Boleta N°xxx Remun Variable Gerente | B31: Bxxx | D31: =+(D5+D6+D7)*0.17 -> 118014
A32: SIDTECH OC 100010 1000 lt vino saldo 80% | B32: FXX | D32: =1250000-250000- 2150*1.19*100 -> 744150
A33: SIDTECH arr 3 reactor Entregas 19 y 21 de Nov y 15 de Enero | B33: F26 | C33: 43864 | D33: 285243
A34: ANALAB preparación mezcla Aperol | B34: F194283 | C34: 43892 | D34: =45500*1.19 -> 54145 | E34: Transfer
A35: VIÑA STA. CAROLINA 1.5X9X12 lt Chardonnay | B35: Boleta N°xxx7282 | C35: 44049 | D35: 48000 | E35: TC | K35: 48000
A36: Av. Ricardo Mahn 2 bidones 30 lt | B36: sin boleta | C36: 44049 | D36: =2500*2 -> 5000 | E36: Transfer | K36: 5000
A37: Flete Vitacura-Viña Sta Carolina-Vitacura | B37: B181419 | C37: 44049 | D37: =(18.6*703/9+1265)*2 -> 5435.7333 | E37: TC EMS | K37: 5436
A38: UNIMARC AGUA AZUCAR | B38: F31909557 | C38: 44053 | D38: 6315 | E38: TC | K38: 6315
A39: CLEAN ICE recarga 9 Kg CO2 | B39: F26833 | C39: 44068 | D39: 16065 | E39: Transfer | AD39: 16065
A43: TOTAL EGRESOS | F43: =SUM(F26:F42) -> 0 | G43: =SUM(G26:G42) -> 0 | H43: =SUM(H26:H42) -> 0 | I43: =SUM(I26:I42) -> 0 | J43: =SUM(J26:J42) -> 0 | K43: =SUM(K26:K42) -> 64751 | L43: =SUM(L26:L42) -> 0 | M43: =SUM(M26:M42) -> 0 | ... AJ43: =SUM(AJ26:AJ42) -> 0
A44: SALDO FINAL | F44: =+F23+F3-F43 -> 62605.584 | G44: =+G3+G23-G43 -> 62605.584 | H44: =+H3+H23-H43 -> 62605.584 | I44: =+I3+I23-I43 -> 62605.584 | J44: =+J3+J23-J43 -> 62605.584 | K44: =+K3+K23-K43 -> -2145.4163 | L44: =+L3+L23-L43 -> -2145.4163 | M44: =+M3+M23-M43 -> -2145.4163 | N44: =+N3+N23-N43 -> -2145.4163 | ... AJ44: =+AJ3+AJ23-AJ43 -> -18210.416

Sheet SEPT-20
B2: N° doc | C2: Fecha | D2: Monto Bruto | E2: Forma Pago | F2: 44075 | G2: 44076 | H2: 44077 | I2: 44078 | J2: 44079 | K2: 44080 | L2: 44081 | M2: 44082 | N2: 44083 | O2: 44084 | P2: 44085 | Q2: 44086 | R2: 44087 | S2: 44088 | T2: 44089 | U2: 44090 | V2: 44091 | W2: 44092 | X2: 44093 | Y2: 44094 | Z2: 44095 | AA2: 44096 | AB2: 44097 | AC2: 44098 | AD2: 44099 | AE2: 44100 | AF2: 44101 | AG2: 44102 | AH2: 44103 | AI2: 44104 | AJ2: TOTAL
A3: SALDO INICIAL | F3: =+'AGO-20'!AJ44 -> -18210.416 | G3: =+F39 -> -18210.416 | H3: =+G39 -> -18210.416 | I3: =+H39 -> -18210.416 | J3: =+I39 -> -18210.416 | K3: =+J39 -> -18210.416 | L3: =+K39 -> -18210.416 | M3: =+L39 -> -18210.416 | N3: =+M39 -> -18210.416 | ... AI3: =+AH39 -> -18210.416
A4: INGRESOS
A5: Factura N° 6 Sofía Jottar | B5: F6 | C5: 43820 | D5: 267000 | AJ5: =SUM(E5:AI5) -> 0
A6: Factura N° 7 Sofía Jottar | B6: F7 | C6: 43836 | D6: 267000 | AJ6: =SUM(E6:AI6) -> 0
A7: Factura N° 8 Sofía Jottar | B7: F8 | C7: 43848 | D7: 160200 | AJ7: =SUM(E7:AI7) -> 0
A8: Factura N° 9 Sofía Jottar | B8: F9 | C8: 43865 | D8: 160200 | AJ8: =SUM(E8:AI8) -> 0
A9: Factura N° 10 Sofía Jottar | B9: F10 | C9: 43866 | D9: 33728 | AJ9: =SUM(E9:AI9) -> 0
A10: Factura N° 11 Sofía Jottar | B10: F11 | C10: 43876 | D10: 160200 | AJ10: =SUM(E10:AI10) -> 0
A11: Factura N° 12 Sofía Jottar | B11: F12 | C11: 43882 | D11: 160200 | AJ11: =SUM(E11:AI11) -> 0
A12: Factura N° 13 Sofía Jottar | B12: F13 | C12: 43889 | D12: 160200 | AJ12: =SUM(E12:AI12) -> 0
A13: Factura N° 14 Sofía Jottar | B13: F14 | C13: 43892 | D13: =28475.41*1.19 -> 33885.738 | AJ13: =SUM(E13:AI13) -> 0
A14: Factura N° 15 Sofía Jottar | B14: F15 | C14: 43904 | D14: 160200 | AJ14: =SUM(E14:AI14) -> 0
A15: Factura N° XX Sofía Jottar SPRITZ | B15: FXX | D15: =4500*60 -> 270000 | E15: por facturar | AJ15: =SUM(E15:AI15) -> 0
A16: SII DEVOLUCION PPM 2019 | C16: 43980 | D16: 10465 | AJ16: =SUM(E16:AI16) -> 0
A17: SUBTOTAL VENTAS | AJ17: =SUM(AJ5:AJ16) -> 0
A18: Aporte LV | F18: 0 | G18: 0
A19: Aporte ML | G19: 0
A20: Remanente IVA | D20: 2001574
A23: TOTAL INGRESOS | F23: =SUM(F5:F22) -> 0 | G23: =SUM(G5:G22) -> 0 | H23: =SUM(H5:H22) -> 0 | I23: =SUM(I5:I22) -> 0 | J23: =SUM(J5:J22) -> 0 | K23: =SUM(K5:K22) -> 0 | L23: =SUM(L5:L22) -> 0 | M23: =SUM(M5:M22) -> 0 | ... AI23: =SUM(AI5:AI22) -> 0
A25: EGRESOS
A26: SIDTECH OC 100006 2 muebles | B26: F21 | C26: 43812 | D26: 559300
A27: Boleta N° xxx EMS Remun Abril 2020 | B27: Bxxx | D27: 500000
A28: Boleta N° xxx EMS Remun Mayo 2020 | B28: Bxxx | D28: 500000
A29: Boleta N° xxx EMS Remun Junio 2020 | B29: Bxxx | D29: =500000/2 -> 250000
A30: Boleta N° xxx EMS Remun Julio 2020 | B30: Bxxx | D30: =500000/2 -> 250000
A31: Boleta N° xxx EMS Remun Agosto 2020 | B31: Bxxx | D31: =500000/2 -> 250000
A32: Boleta N°xxx Remun Variable Gerente | B32: Bxxx | D32: =+(D5+D6+D7)*0.17 -> 118014
A33: SIDTECH OC 100010 1000 lt vino saldo 80% | B33: FXX | D33: =1250000-250000- 2150*1.19*100 -> 744150
A34: SIDTECH arr 3 reactor Entregas 19 y 21 de Nov y 15 de Enero | B34: F26 | C34: 43864 | D34: 285243
A35: ANALAB preparación mezcla Aperol | B35: F194283 | C35: 43892 | D35: =45500*1.19 -> 54145 | E35: Transfer
A36: Oficina Virtual al 16 de Octubre | D36: 109000
A38: TOTAL EGRESOS | F38: =SUM(F26:F37) -> 0 | G38: =SUM(G26:G37) -> 0 | H38: =SUM(H26:H37) -> 0 | I38: =SUM(I26:I37) -> 0 | J38: =SUM(J26:J37) -> 0 | K38: =SUM(K26:K37) -> 0 | L38: =SUM(L26:L37) -> 0 | M38: =SUM(M26:M37) -> 0 | ... AI38: =SUM(AI26:AI37) -> 0
A39: SALDO FINAL | F39: =+F23+F3-F38 -> -18210.416 | G39: =+G3+G23-G38 -> -18210.416 | H39: =+H3+H23-H38 -> -18210.416 | I39: =+I3+I23-I38 -> -18210.416 | J39: =+J3+J23-J38 -> -18210.416 | K39: =+K3+K23-K38 -> -18210.416 | L39: =+L3+L23-L38 -> -18210.416 | M39: =+M3+M23-M38 -> -18210.416 | N39: =+N3+N23-N38 -> -18210.416 | ... AI39: =+AI3+AI23-AI38 -> -18210.416

Sheet OCT-20
B2: N° doc | C2: Fecha | D2: Monto Bruto | E2: Forma Pago | F2: 44105 | G2: 44106 | H2: 44107 | I2: 44108 | J2: 44109 | K2: 44110 | L2: 44111 | M2: 44112 | N2: 44113 | O2: 44114 | P2: 44115 | Q2: 44116 | R2: 44117 | S2: 44118 | T2: 44119 | U2: 44120 | V2: 44121 | W2: 44122 | X2: 44123 | Y2: 44124 | Z2: 44125 | AA2: 44126 | AB2: 44127 | AC2: 44128 | AD2: 44129 | AE2: 44130 | AF2: 44131 | AG2: 44132 | AH2: 44133 | AI2: 44134 | AJ2: 44135 | AK2: TOTAL
A3: SALDO INICIAL | F3: =+'SEPT-20'!AI39 -> -18210.416 | G3: =+F51 -> -18210.416 | H3: =+G51 -> -18210.416 | I3: =+H51 -> -18210.416 | J3: =+I51 -> -18210.416 | K3: =+J51 -> -18210.416 | L3: =+K51 -> -18210.416 | M3: =+L51 -> -18210.416 | N3: =+M51 -> -18210.416 | ... AJ3: =+AI51 -> 164750.04
A4: INGRESOS
A5: Factura N° 6 Sofía Jottar | B5: F6 | C5: 43820 | D5: 267000 | AK5: =SUM(F5:AJ5) -> 0
A6: Factura N° 7 Sofía Jottar | B6: F7 | C6: 43836 | D6: 267000 | AK6: =SUM(F6:AJ6) -> 0
A7: Factura N° 8 Sofía Jottar | B7: F8 | C7: 43848 | D7: 160200 | AK7: =SUM(F7:AJ7) -> 0
A8: Factura N° 9 Sofía Jottar | B8: F9 | C8: 43865 | D8: 160200 | AK8: =SUM(F8:AJ8) -> 0
A9: Factura N° 10 Sofía Jottar | B9: F10 | C9: 43866 | D9: 33728 | AK9: =SUM(F9:AJ9) -> 0
A10: Factura N° 11 Sofía Jottar | B10: F11 | C10: 43876 | D10: 160200 | AK10: =SUM(F10:AJ10) -> 0
A11: Factura N° 12 Sofía Jottar | B11: F12 | C11: 43882 | D11: 160200 | AK11: =SUM(F11:AJ11) -> 0
A12: Factura N° 13 Sofía Jottar | B12: F13 | C12: 43889 | D12: 160200 | AK12: =SUM(F12:AJ12) -> 0
A13: Factura N° 14 Sofía Jottar | B13: F14 | C13: 43892 | D13: =28475.41*1.19 -> 33885.738 | AK13: =SUM(F13:AJ13) -> 0
A14: Factura N° 15 Sofía Jottar | B14: F15 | C14: 43904 | D14: 160200 | AK14: =SUM(F14:AJ14) -> 0
A15: Factura N° XX Sofía Jottar SPRITZ | B15: FXX | D15: =4500*60 -> 270000 | E15: por facturar | AK15: =SUM(F15:AJ15) -> 0
A16: Factura N° 25 Marina | B16: F25 | C16: 44127 | D16: 62665 | AI16: 62665 | AK16: =SUM(F16:AJ16) -> 62665
A17: SUBTOTAL VENTAS | AK17: =SUM(AK5:AK16) -> 62665
A18: CREDITO BANCO ESTADO | T18: 500000
A19: Gastos no reembolsado EMS acumuldo al 14 Oct | S19: 18210
A20: Aporte LV | F20: 0 | G20: 0
A21: Aporte ML | G21: 0
A24: TOTAL INGRESOS | F24: =SUM(F5:F23) -> 0 | G24: =SUM(G5:G23) -> 0 | H24: =SUM(H5:H23) -> 0 | I24: =SUM(I5:I23) -> 0 | J24: =SUM(J5:J23) -> 0 | K24: =SUM(K5:K23) -> 0 | L24: =SUM(L5:L23) -> 0 | M24: =SUM(M5:M23) -> 0 | ... AJ24: =SUM(AJ5:AJ23) -> 0
A26: EGRESOS
A27: SIDTECH OC 100006 2 muebles | B27: F21 | C27: 43812 | D27: =559300*0 -> 0
A28: Boleta N° xxx EMS Remun Abril 2020 | B28: Bxxx | D28: 500000
A29: Boleta N° xxx EMS Remun Mayo 2020 | B29: Bxxx | D29: 500000
A30: Boleta N° xxx EMS Remun Junio 2020 | B30: Bxxx | D30: =500000/2 -> 250000
A31: Boleta N° xxx EMS Remun Julio 2020 | B31: Bxxx | D31: =500000/2 -> 250000
A32: Boleta N° xxx EMS Remun Agosto 2020 | B32: Bxxx | D32: =500000/2 -> 250000
A33: Boleta N°xxx Remun Variable Gerente | B33: Bxxx | D33: =+(D5+D6+D7)*0.17 -> 118014 | AI33: =+(AJ5+AJ6+AJ7)*0.17 -> 0 | AJ33: =SUM(AJ8:AJ15)*0.17 -> 0
A34: SIDTECH OC 100010 1000 lt vino saldo 80% | B34: FXX | D34: =(1250000-250000- 2150*1.19*100)*0 -> 0 | AJ34: =(1250000-250000- 2150*1.19*100)*0 -> 0
A35: SIDTECH arr 3 reactor Entregas 19 y 21 de Nov y 15 de Enero | B35: F26 | C35: 43864 | D35: =285243*0 -> 0 | AJ35: =100*850*1.19*0 -> 0
A36: Oficina Virtual al 16 de Octubre | D36: 171000 | E36: Transfer Estado | U36: 171000
A37: Flete Vitacura-Emb.La Colonia Peñaflor-Vitacura | C37: 44104 | D37: =1509.36+2936.91+601+41+525+259+57.4*2*822/9 -> 16357.337 | E37: Transfer Estado | Z37: =1509.36+2936.91+601+41+525+259+57.4*2*822/9 -> 16357.337
A38: LANCER arriendo 1 equipo | B38: F1069066 | C38: 44112 | D38: =60000*1.19 -> 71400 | E38: Transfer Estado | V38: =60000*1.19 -> 71400
A39: Flete Vitacura-SIDTECH San Joaquin-Vitacura | C39: 44125 | D39: =1509.36+2936.91+601+41+525+259+39.2*822/9 -> 9452.5367 | E39: Transfer Estado | Z39: =1509.36+2936.91+601+41+525+259+39.2*822/9 -> 9452.5367
A40: Flete Vitacura-Renca-Requinoa-Recoleta-Vitacura | C40: 44126 | D40: =2615+1313+389+788+407+560+644+377+337+614+285+1237+3800+2700*2+283*780/9 -> 43292.667 | E40: Transfer Estado | AA40: =2615+1313+389+788+407+560+644+377+337+614+285+1237+3800+2700*2+283*780/9 -> 43292.667
A41: LANCER embolsado+ caja 40 lt | B41: F1069201 | C41: 44126 | D41: =12800*1.19 -> 15232 | E41: Transfer Estado | AB41: =12800*1.19 -> 15232
A42: TAGLER | B42: F11147260 | C42: 44126 | D42: =11500*1.19 -> 13685 | E42: Transfer Estado | AA42: =11500*1.19 -> 13685
A43: firma.cl | B43: F34231 | C43: 44127 | D43: 14161 | E43: TC | AB43: 14161
A44: HOMECENTER Pintura | B44: F107907716 | C44: 44127 | D44: 5489 | E44: TC | AB44: 5489
...

Sheet NOV-20
B2: N° doc | C2: Fecha | D2: Monto Bruto | E2: Forma Pago | F2: 44136 | G2: 44137 | H2: 44138 | I2: 44139 | J2: 44140 | K2: 44141 | L2: 44142 | M2: 44143 | N2: 44144 | O2: 44145 | P2: 44146 | Q2: 44147 | R2: 44148 | S2: 44149 | T2: 44150 | U2: 44151 | V2: 44152 | W2: 44153 | X2: 44154 | Y2: 44155 | Z2: 44156 | AA2: 44157 | AB2: 44158 | AC2: 44159 | AD2: 44160 | AE2: 44161 | AF2: 44162 | AG2: 44163 | AH2: 44164 | AI2: 44165 | AJ2: TOTAL
A3: SALDO INICIAL | F3: =+'OCT-20'!AJ51 -> 164750.04 | G3: =+F66 -> 164750.04 | H3: =+G66 -> 196083.04 | I3: =+H66 -> 352746.04 | J3: =+I66 -> 339117.04 | K3: =+J66 -> 339117.04 | L3: =+K66 -> 248606.04 | M3: =+L66 -> 248606.04 | N3: =+M66 -> 248606.04 | ... AI3: =+AH66 -> 2093888.1
A4: INGRESOS
A5: Factura N° 6 Sofía Jottar | B5: F6 | C5: 43820 | D5: 267000 | AC5: 267000 | AI5: 0 | AJ5: =SUM(E5:AI5) -> 267000
A6: Factura N° 7 Sofía Jottar | B6: F7 | C6: 43836 | D6: 267000 | AC6: =350000-AC5 -> 83000 | AD6: 184000 | AI6: 0 | AJ6: =SUM(E6:AI6) -> 267000
A7: Factura N° 8 Sofía Jottar | B7: F8 | C7: 43848 | D7: 160200 | AI7: 0 | AJ7: =SUM(E7:AI7) -> 0
A8: Factura N° 9 Sofía Jottar | B8: F9 | C8: 43865 | D8: 160200 | AI8: 0 | AJ8: =SUM(E8:AI8) -> 0
A9: Factura N° 10 Sofía Jottar | B9: F10 | C9: 43866 | D9: 33728 | AI9: 0 | AJ9: =SUM(E9:AI9) -> 0
A10: Factura N° 11 Sofía Jottar | B10: F11 | C10: 43876 | D10: 160200 | AI10: 0 | AJ10: =SUM(E10:AI10) -> 0
A11: Factura N° 12 Sofía Jottar | B11: F12 | C11: 43882 | D11: 160200 | AI11: 0 | AJ11: =SUM(E11:AI11) -> 0
A12: Factura N° 13 Sofía Jottar | B12: F13 | C12: 43889 | D12: 160200 | AI12: 0 | AJ12: =SUM(E12:AI12) -> 0
A13: Factura N° 14 Sofía Jottar | B13: F14 | C13: 43892 | D13: =28475.41*1.19 -> 33885.738 | AI13: 0 | AJ13: =SUM(E13:AI13) -> 0
A14: Factura N° 15 Sofía Jottar | B14: F15 | C14: 43904 | D14: 160200 | AI14: 0 | AJ14: =SUM(E14:AI14) -> 0
A15: Factura N° XX Sofía Jottar SPRITZ | B15: FXX | D15: =4500*60 -> 270000 | E15: por facturar | AI15: 0 | AJ15: =SUM(E15:AI15) -> 0
A16: Factura N° 26 Marina | B16: F26 | C16: 44128 | D16: 31333 | G16: 31333 | AI16: 0 | AJ16: =SUM(E16:AI16) -> 31333
A17: Factura N° 27 Marina | B17: F27 | C17: 44133 | D17: 31333 | H17: 31333 | AI17: 0 | AJ17: =SUM(E17:AI17) -> 31333
A18: Factura N° 28 Marina | B18: F28 | C18: 44136 | D18: 62665 | H18: 62665 | AI18: 0 | AJ18: =SUM(E18:AI18) -> 62665
A19: Factura N° 29 Marina | B19: F29 | C19: 44136 | D19: 93998 | H19: =156663-31333-62665 -> 62665 | AI19: 0 | AJ19: =SUM(E19:AI19) -> 62665
A20: Factura N° 30 Marina | B20: F30 | C20: 44148 | D20: 125331 | W20: 156664 | AI20: 0 | AJ20: =SUM(E20:AI20) -> 156664
A21: Factura N° 31 Marina | B21: F31 | C21: 44155 | D21: 62665 | AI21: 0 | AJ21: =SUM(E21:AI21) -> 0
A22: Factura N° 32 Entretoros | B22: F32 | C22: 44155 | D22: 115199 | AI22: 0 | AJ22: =SUM(E22:AI22) -> 0
A23: Factura N° 33Marina | B23: F33 | C23: 44161 | D23: =26330*4*1.19 -> 125330.8 | AI23: 0 | AJ23: =SUM(E23:AI23) -> 0
A24: SUBTOTAL VENTAS | AJ24: =SUM(AJ5:AJ23) -> 878660
A25: SII DEVOLUCION PPM 2019 | C25: 43980 | D25: 10465
A26: Aporte LV | D26: =250000+1950000 -> 2200000 | F26: 0 | G26: 0 | O26: 250000 | R26: 1950000
A27: Aporte ML | G27: 0
A28: SENCE subsidio | R28: 16666
A29: Remanente IVA | D29: 2001574
A32: TOTAL INGRESOS | F32: =SUM(F5:F31) -> 0 | G32: =SUM(G5:G31) -> 31333 | H32: =SUM(H5:H31) -> 156663 | I32: =SUM(I5:I31) -> 0 | J32: =SUM(J5:J31) -> 0 | K32: =SUM(K5:K31) -> 0 | L32: =SUM(L5:L31) -> 0 | M32: =SUM(M5:M31) -> 0 | ... AI32: =SUM(AI5:AI31) -> 0
A34: EGRESOS
A35: Boleta N° 126 EMS Remun Abril 2020 | B35: B126 | D35: 500000 | U35: 500000 | AI35: 0
A36: Boleta N° xxx EMS Remun Mayo 2020 | B36: Bxxx | D36: 500000 | AI36: 0
A37: Boleta N° xxx EMS Remun Junio 2020 | B37: Bxxx | D37: =500000/2 -> 250000 | AI37: 0
A38: Boleta N° xxx EMS Remun Julio 2020 | B38: Bxxx | D38: =500000/2 -> 250000 | AI38: 0
A39: Boleta N° xxx EMS Remun Agosto 2020 | B39: Bxxx | D39: =500000/2 -> 250000 | AI39: 0
A40: Boleta N° xxx EMS Remun Sept 2020 | B40: Bxxx | D40: 250000 | AI40: 0
A41: Boleta N° xxx EMS Remun Oct 2020 | B41: Bxxx | D41: 500000 | AI41: 0
A42: Boleta N° xxx EMS Remun Nov 2020 | B42: Bxxx | D42: 500000 | AI42: 0
A43: Boleta N°xxx Remun Variable Gerente | B43: Bxxx | D43: =+AI43 -> 0 | AI43: 0
A44: ANALAB preparación mezcla Aperol | B44: F194283 | C44: 43892 | D44: =45500*1.19 -> 54145 | E44: Transfer | U44: 30000
...

Sheet DIC-20
B2: N° doc | C2: Fecha | D2: Monto Bruto | E2: Forma Pago | F2: 44166 | G2: 44167 | H2: 44168 | I2: 44169 | J2: 44170 | K2: 44171 | L2: 44172 | M2: 44173 | N2: 44174 | O2: 44175 | P2: 44176 | Q2: 44177 | R2: 44178 | S2: 44179 | T2: 44180 | U2: 44181 | V2: 44182 | W2: 44183 | X2: 44184 | Y2: 44185 | Z2: 44186 | AA2: 44187 | AB2: 44188 | AC2: 44189 | AD2: 44190 | AE2: 44191 | AF2: 44192 | AG2: 44193 | AH2: 44194 | AI2: 44195 | AJ2: 44196 | AK2: TOTAL
A3: SALDO INICIAL | F3: =+'NOV-20'!AI66 -> 2093888.1 | G3: =+F62 -> 2048758.1 | H3: =+G62 -> 2212660.1 | I3: =+H62 -> 2212660.1 | J3: =+I62 -> 2212660.1 | K3: =+J62 -> 2212660.1 | L3: =+K62 -> 2212660.1 | M3: =+L62 -> 2212660.1 | N3: =+M62 -> 2212660.1 | ... AJ3: =+AI62 -> 1552648.3
A4: INGRESOS
A5: Factura N° 8 Sofía Jottar | B5: F8 | C5: 43848 | D5: 160200 | AJ5: 0 | AK5: =SUM(F5:AJ5) -> 0
A6: Factura N° 9 Sofía Jottar | B6: F9 | C6: 43865 | D6: 160200 | AJ6: 0 | AK6: =SUM(F6:AJ6) -> 0
A7: Factura N° 10 Sofía Jottar | B7: F10 | C7: 43866 | D7: 33728 | AJ7: 0 | AK7: =SUM(F7:AJ7) -> 0
A8: Factura N° 11 Sofía Jottar | B8: F11 | C8: 43876 | D8: 160200 | AJ8: 0 | AK8: =SUM(F8:AJ8) -> 0
A9: Factura N° 12 Sofía Jottar | B9: F12 | C9: 43882 | D9: 160200 | AJ9: 0 | AK9: =SUM(F9:AJ9) -> 0
A10: Factura N° 13 Sofía Jottar | B10: F13 | C10: 43889 | D10: 160200 | AJ10: 0 | AK10: =SUM(F10:AJ10) -> 0
A11: Factura N° 14 Sofía Jottar | B11: F14 | C11: 43892 | D11: =28475.41*1.19 -> 33885.738 | AJ11: 0 | AK11: =SUM(F11:AJ11) -> 0
A12: Factura N° 15 Sofía Jottar | B12: F15 | C12: 43904 | D12: 160200 | AJ12: 0 | AK12: =SUM(F12:AJ12) -> 0
A13: Factura N° XX Sofía Jottar SPRITZ | B13: FXX | D13: =4500*60 -> 270000 | E13: por facturar | AJ13: 0 | AK13: =SUM(F13:AJ13) -> 0
A14: Factura N° 31 Marina | B14: F31 | C14: 44155 | D14: 62665 | G14: 125331 | N14: -125331 | P14: 62665 | AK14: =SUM(F14:AJ14) -> 62665
A15: Factura N° 32 Entretoros | B15: F32 | C15: 44155 | D15: 115199 | AC15: =+D15 -> 115199 | AK15: =SUM(F15:AJ15) -> 115199
A16: Factura N° 33Marina | B16: F33 | C16: 44161 | D16: =26330*4*1.19 -> 125330.8 | G16: 125331 | AK16: =SUM(F16:AJ16) -> 125331
A17: Factura N° 34Marina | B17: F34 | C17: 44174 | D17: 62665 | P17: 62666 | AK17: =SUM(F17:AJ17) -> 62666
A18: Factura N° 35 Entretoros | B18: F35 | C18: 44175 | D18: 31333 | AC18: =+D18 -> 31333 | AK18: =SUM(F18:AJ18) -> 31333
A19: Factura N° 36Marina | B19: F36 | C19: 44180 | D19: 31333 | U19: 31333 | AK19: =SUM(F19:AJ19) -> 31333
A20: Factura N° 37Marina | B20: F37 | C20: 44186 | D20: 62666 | AB20: 62666 | AK20: =SUM(F20:AJ20) -> 62666
A21: Factura N° 38Marina | B21: F38 | C21: 44187 | D21: 34604 | AB21: 34604 | AK21: =SUM(F21:AJ21) -> 34604
A22: SUBTOTAL VENTAS | AK22: =SUM(AK5:AK21) -> 525797
A23: SII DEVOLUCION PPM 2019 | C23: 43980 | D23: 10465
A24: Aporte LV | D24: 0 | F24: 0 | G24: 0
A25: Aporte ML | G25: 0
A26: SENCE subsidio
A27: Remanente IVA | D27: 2001574 | AJ27: 0
A30: TOTAL INGRESOS | B30: 2020 | F30: =SUM(F5:F29) -> 0 | G30: =SUM(G5:G29) -> 250662 | H30: =SUM(H5:H29) -> 0 | I30: =SUM(I5:I29) -> 0 | J30: =SUM(J5:J29) -> 0 | K30: =SUM(K5:K29) -> 0 | L30: =SUM(L5:L29) -> 0 | M30: =SUM(M5:M29) -> 0 | ... AI30: =SUM(AI5:AI29) -> 0
A32: EGRESOS
A33: Boleta N° 127 EMS Remun Mayo 2020 | B33: B127 | D33: 500000 | P33: 500000
A34: Boleta N° xxx EMS Remun Junio 2020 | B34: Bxxx | D34: =500000/2 -> 250000 | AJ34: 0
A35: Boleta N° xxx EMS Remun Julio 2020 | B35: Bxxx | D35: =500000/2 -> 250000 | AJ35: 0
A36: Boleta N° xxx EMS Remun Agosto 2020 | B36: Bxxx | D36: =500000/2 -> 250000 | AJ36: 0
A37: Boleta N° xxx EMS Remun Sept 2020 | B37: Bxxx | D37: 250000 | AJ37: 0
A38: Boleta N° xxx EMS Remun Oct 2020 | B38: Bxxx | D38: 500000 | AJ38: 0
A39: Boleta N° xxx EMS Remun Nov 2020 | B39: Bxxx | D39: 500000 | AJ39: 0
A40: Boleta N°xxx Remun Variable Gerente | B40: Bxxx | D40: =+AJ40 -> 0 | AJ40: 0
A41: HARRY PLOTTER | B41: F36586 | C41: 44166 | D41: 45130 | E41: Transfer | F41: 45130
A42: Rebeca Trincado 4 ruedas 10 cm + 4 con freno | B42: F6499 | C42: 44167 | D42: 22000 | E42: transfer | G42: 22000
A43: Elias Becerra modificación mueble chico | C43: 44167 | D43: 60000 | E43: transfer | G43: 60000
A44: Flete Vitacura Chicureo Vitacura | C44: 44167 | D44: =+(25.6*2)*790/9 -> 4494.2222 | E44: transfer | P44: =+(25.6*2)*790/9 -> 4494.2222
...

Sheet ENE-21
B2: N° doc | C2: Fecha | D2: Monto Bruto | E2: Forma Pago | F2: 44197 | G2: 44198 | H2: 44199 | I2: 44200 | J2: 44201 | K2: 44202 | L2: 44203 | M2: 44204 | N2: 44205 | O2: 44206 | P2: 44207 | Q2: 44208 | R2: 44209 | S2: 44210 | T2: 44211 | U2: 44212 | V2: 44213 | W2: 44214 | X2: 44215 | Y2: 44216 | Z2: 44217 | AA2: 44218 | AB2: 44219 | AC2: 44220 | AD2: 44221 | AE2: 44222 | AF2: 44223 | AG2: 44224 | AH2: 44225 | AI2: 44226 | AJ2: 44227 | AK2: TOTAL
A3: SALDO INICIAL | F3: =+'DIC-20'!AJ62 -> 1552648.3 | G3: =+F66 -> 1552648.3 | H3: =+G66 -> 1552648.3 | I3: =+H66 -> 1552648.3 | J3: =+I66 -> 1552648.3 | K3: =+J66 -> 1552648.3 | L3: =+K66 -> 1380747.3 | M3: =+L66 -> 1123477.3 | N3: =+M66 -> 1123477.3 | ... AJ3: =+AI66 -> 475165.43
A4: INGRESOS
A5: Factura N° 8 Sofía Jottar | B5: F8 | C5: 43848 | D5: 160200 | AH5: 250000 | AJ5: 0 | AK5: =SUM(F5:AJ5) -> 250000
A6: Factura N° 9 Sofía Jottar | B6: F9 | C6: 43865 | D6: 160200 | AI6: 70400 | AJ6: 0 | AK6: =SUM(F6:AJ6) -> 70400
A7: Factura N° 10 Sofía Jottar | B7: F10 | C7: 43866 | D7: 33728 | AJ7: 0 | AK7: =SUM(F7:AJ7) -> 0
A8: Factura N° 11 Sofía Jottar | B8: F11 | C8: 43876 | D8: 160200 | AJ8: 0 | AK8: =SUM(F8:AJ8) -> 0
A9: Factura N° 12 Sofía Jottar | B9: F12 | C9: 43882 | D9: 160200 | AJ9: 0 | AK9: =SUM(F9:AJ9) -> 0
A10: Factura N° 13 Sofía Jottar | B10: F13 | C10: 43889 | D10: 160200 | AJ10: 0 | AK10: =SUM(F10:AJ10) -> 0
A11: Factura N° 14 Sofía Jottar | B11: F14 | C11: 43892 | D11: =28475.41*1.19 -> 33885.738 | AJ11: 0 | AK11: =SUM(F11:AJ11) -> 0
A12: Factura N° 15 Sofía Jottar | B12: F15 | C12: 43904 | D12: 160200 | AJ12: 0 | AK12: =SUM(F12:AJ12) -> 0
A13: Factura N° XX Sofía Jottar SPRITZ | B13: FXX | D13: =4500*60 -> 270000 | E13: por facturar | AJ13: 0 | AK13: =SUM(F13:AJ13) -> 0
A14: Factura N° 39 Entretoros | B14: F39 | C14: 44194 | D14: 31333 | AF14: 31333 | AK14: =SUM(F14:AJ14) -> 31333
A15: Factura N° 40Marina | B15: F40 | C15: 44194 | D15: 62665 | Y15: 62665 | AK15: =SUM(F15:AJ15) -> 62665
A16: Factura N° 41Marina | B16: F41 | C16: 44202 | D16: 62665 | Y16: =124817-Y15 -> 62152 | AF16: 515 | AK16: =SUM(F16:AJ16) -> 62667
A17: Factura N°42Marina ARRIENDO VAR DIC2020 | B17: F42 | C17: 44207 | D17: 51885 | AF17: 51885 | AK17: =SUM(F17:AJ17) -> 51885
A18: Factura N°43Marina | B18: F43 | C18: 44207 | D18: 47600 | AF18: 47600 | AK18: =SUM(F18:AJ18) -> 47600
A19: Factura N° 44 Entretoros | B19: F44 | C19: 44209 | D19: 31333 | AK19: =SUM(F19:AJ19) -> 0
A20: Factura N°45Marina | B20: F45 | C20: 44209 | D20: 156664 | AK20: =SUM(F20:AJ20) -> 0
A21: SUBTOTAL VENTAS | AK21: =SUM(AK5:AK20) -> 576550
A22: SII DEVOLUCION PPM 2019 | C22: 43980 | D22: 10465 | AJ22: 0
A23: Aporte LV | D23: 0 | F23: 0 | G23: 0
A24: Aporte ML | G24: 0
A25: SENCE subsidio
A26: Remanente IVA | D26: 2001574 | AJ26: 0
A29: TOTAL INGRESOS | F29: =SUM(F5:F28) -> 0 | G29: =SUM(G5:G28) -> 0 | H29: =SUM(H5:H28) -> 0 | I29: =SUM(I5:I28) -> 0 | J29: =SUM(J5:J28) -> 0 | K29: =SUM(K5:K28) -> 0 | L29: =SUM(L5:L28) -> 0 | M29: =SUM(M5:M28) -> 0 | ... AJ29: =SUM(AJ5:AJ28) -> 0
A31: EGRESOS
A32: Boleta N° xxx EMS Remun Junio 2020 | B32: Bxxx | D32: =500000/2 -> 250000 | AJ32: 0
A33: Boleta N° xxx EMS Remun Julio 2020 | B33: Bxxx | D33: =500000/2 -> 250000 | AJ33: 0
A34: Boleta N° xxx EMS Remun Agosto 2020 | B34: Bxxx | D34: =500000/2 -> 250000 | AJ34: 0
A35: Boleta N° xxx EMS Remun Sept 2020 | B35: Bxxx | D35: 250000 | AJ35: 0
A36: Boleta N° xxx EMS Remun Oct 2020 | B36: Bxxx | D36: 500000 | AJ36: 0
A37: Boleta N° xxx EMS Remun Nov 2020 | B37: Bxxx | D37: 500000 | AJ37: 0
A38: Boleta N° xxx EMS Remun Dic2020 | B38: Bxxx | D38: 500000 | AJ38: 0
A39: Boleta N°xxx Remun Variable Gerente | B39: Bxxx | D39: =+AJ39 -> 0 | AJ39: 0
A40: Flete Vitacura Chicureo Vitacura | C40: 44194 | D40: =+(25.6*2)*790/9 -> 4494.2222 | P40: =+(25.6*2)*790/9 -> 4494.2222 | AJ40: 0
A41: SABORES goma Xanthan escencia ginger colorante caramelo | B41: F95603 Pedido 27963 | C41: 44155 | D41: 7270 | E41: Transfer | L41: 7270
A42: LANCER EMBOLSADO | B42: F1070013 | C42: 44182 | D42: 121856
A43: ANTAWARA | B43: F5 | C43: 44195 | D43: 240975
A44: Flete Vitacura-Chicureo-Vitacura | C44: 44201 | D44: =(23.4*2)*810/9 -> 4212 | P44: =(23.4*2)*810/9 -> 4212
...

Sheet FEB-21
